Traceback (most recent call last):
  File "/home/vljchr004/msc-hpc/round2/feedforward/troubleshoot/one_training_example/round2_model1.py", line 169, in <module>
    verbose=2)#,
  File "/usr/local/lib/python3.5/dist-packages/tensorflow/python/keras/engine/training.py", line 1536, in fit
    validation_split=validation_split)
  File "/usr/local/lib/python3.5/dist-packages/tensorflow/python/keras/engine/training.py", line 992, in _standardize_user_data
    class_weight, batch_size)
  File "/usr/local/lib/python3.5/dist-packages/tensorflow/python/keras/engine/training.py", line 1117, in _standardize_weights
    exception_prefix='input')
  File "/usr/local/lib/python3.5/dist-packages/tensorflow/python/keras/engine/training_utils.py", line 332, in standardize_input_data
    ' but got array with shape ' + str(data_shape))
ValueError: Error when checking input: expected dense_input to have shape (32,) but got array with shape (1,)
