Loading software/NAMD-2.13-CUDA
  Loading requirement: compilers/gcc820 mpi/openmpi-3.1.2 cuda/cuda-9.2
[34mINFO:   [0m Could not find any NVIDIA binaries on this host!
Traceback (most recent call last):
  File "/usr/local/lib/python3.5/dist-packages/tensorflow/python/pywrap_tensorflow.py", line 58, in <module>
    from tensorflow.python.pywrap_tensorflow_internal import *
  File "/usr/local/lib/python3.5/dist-packages/tensorflow/python/pywrap_tensorflow_internal.py", line 28, in <module>
    _pywrap_tensorflow_internal = swig_import_helper()
  File "/usr/local/lib/python3.5/dist-packages/tensorflow/python/pywrap_tensorflow_internal.py", line 24, in swig_import_helper
    _mod = imp.load_module('_pywrap_tensorflow_internal', fp, pathname, description)
  File "/usr/lib/python3.5/imp.py", line 242, in load_module
    return load_dynamic(name, filename, file)
  File "/usr/lib/python3.5/imp.py", line 342, in load_dynamic
    return _load(spec)
ImportError: libcuda.so.1: cannot open shared object file: No such file or directory

During handling of the above exception, another exception occurred:

Traceback (most recent call last):
  File "/home/vljchr004/msc-hpc/round4/round3_cnn5.py", line 102, in <module>
    from tensorflow.keras.utils import to_categorical
  File "/usr/local/lib/python3.5/dist-packages/tensorflow/__init__.py", line 24, in <module>
    from tensorflow.python import pywrap_tensorflow  # pylint: disable=unused-import
  File "/usr/local/lib/python3.5/dist-packages/tensorflow/python/__init__.py", line 49, in <module>
    from tensorflow.python import pywrap_tensorflow
  File "/usr/local/lib/python3.5/dist-packages/tensorflow/python/pywrap_tensorflow.py", line 74, in <module>
    raise ImportError(msg)
ImportError: Traceback (most recent call last):
  File "/usr/local/lib/python3.5/dist-packages/tensorflow/python/pywrap_tensorflow.py", line 58, in <module>
    from tensorflow.python.pywrap_tensorflow_internal import *
  File "/usr/local/lib/python3.5/dist-packages/tensorflow/python/pywrap_tensorflow_internal.py", line 28, in <module>
    _pywrap_tensorflow_internal = swig_import_helper()
  File "/usr/local/lib/python3.5/dist-packages/tensorflow/python/pywrap_tensorflow_internal.py", line 24, in swig_import_helper
    _mod = imp.load_module('_pywrap_tensorflow_internal', fp, pathname, description)
  File "/usr/lib/python3.5/imp.py", line 242, in load_module
    return load_dynamic(name, filename, file)
  File "/usr/lib/python3.5/imp.py", line 342, in load_dynamic
    return _load(spec)
ImportError: libcuda.so.1: cannot open shared object file: No such file or directory


Failed to load the native TensorFlow runtime.

See https://www.tensorflow.org/install/errors

for some common reasons and solutions.  Include the entire stack trace
above this error message when asking for help.
